<?xml version="1.0" encoding="utf-8"?>
<!-- This URDF was automatically created by SolidWorks to URDF Exporter! Originally created by Stephen Brawner (brawner@gmail.com) 
     Commit Version: 1.6.0-4-g7f85cfe  Build Version: 1.6.7995.38578
     For more information, please see http://wiki.ros.org/sw_urdf_exporter -->
<robot
  name="B_snake_URDF.SLDASM">
  <link
    name="base_link">
    <inertial>
      <origin
        xyz="-6.0019E-19 -0.025 1.5308E-18"
        rpy="0 0 0" />
      <mass
        value="0.0014137" />
      <inertia
        ixx="3.0901E-07"
        ixy="4.5457E-39"
        ixz="-1.5358E-40"
        iyy="2.8981E-08"
        iyz="1.7147E-23"
        izz="3.0901E-07" />
    </inertial>
    <visual>
      <origin
        xyz="0 0 0"
        rpy="0 0 0" />
      <geometry>
        <mesh
          filename="package://B_snake_URDF.SLDASM/meshes/base_link.STL" />
      </geometry>
      <material
        name="">
        <color
          rgba="0.6 0.6 0.6 1" />
      </material>
    </visual>
    <collision>
      <origin
        xyz="0 0 0"
        rpy="0 0 0" />
      <geometry>
        <mesh
          filename="package://B_snake_URDF.SLDASM/meshes/base_link.STL" />
      </geometry>
    </collision>
  </link>
  <link
    name="snake_start_link">
    <inertial>
      <origin
        xyz="1.2416E-09 -4.4549E-05 -0.0095707"
        rpy="0 0 0" />
      <mass
        value="0.00071324" />
      <inertia
        ixx="3.1719E-08"
        ixy="-2.2099E-14"
        ixz="2.9749E-15"
        iyy="3.1792E-08"
        iyz="3.6371E-10"
        izz="8.4865E-09" />
    </inertial>
    <visual>
      <origin
        xyz="0 0 0"
        rpy="0 0 0" />
      <geometry>
        <mesh
          filename="package://B_snake_URDF.SLDASM/meshes/snake_start_link.STL" />
      </geometry>
      <material
        name="">
        <color
          rgba="0.79216 0.81961 0.93333 1" />
      </material>
    </visual>
    <collision>
      <origin
        xyz="0 0 0"
        rpy="0 0 0" />
      <geometry>
        <mesh
          filename="package://B_snake_URDF.SLDASM/meshes/snake_start_link.STL" />
      </geometry>
    </collision>
  </link>
  <joint
    name="base_joint"
    type="prismatic">
    <origin
      xyz="0 -0.065 0"
      rpy="1.5708 0 0" />
    <parent
      link="base_link" />
    <child
      link="snake_start_link" />
    <axis
      xyz="0 0 1" />
    <limit
      lower="0"
      upper="0.2"
      effort="10"
      velocity="0.05" />
  </joint>
  <link
    name="shoulder_link">
    <inertial>
      <origin
        xyz="5.7843E-08 -0.00055751 0.0025749"
        rpy="0 0 0" />
      <mass
        value="0.00011415" />
      <inertia
        ixx="7.4251E-10"
        ixy="-5.3952E-14"
        ixz="1.8424E-14"
        iyy="8.8662E-10"
        iyz="-4.9693E-12"
        izz="1.2304E-09" />
    </inertial>
    <visual>
      <origin
        xyz="0 0 0"
        rpy="0 0 0" />
      <geometry>
        <mesh
          filename="package://B_snake_URDF.SLDASM/meshes/shoulder_link.STL" />
      </geometry>
      <material
        name="">
        <color
          rgba="0.79216 0.81961 0.93333 1" />
      </material>
    </visual>
    <collision>
      <origin
        xyz="0 0 0"
        rpy="0 0 0" />
      <geometry>
        <mesh
          filename="package://B_snake_URDF.SLDASM/meshes/shoulder_link.STL" />
      </geometry>
    </collision>
  </link>
  <joint
    name="shoulder_joint_prox"
    type="revolute">
    <origin
      xyz="0 0 0.0025"
      rpy="0 0 0" />
    <parent
      link="snake_start_link" />
    <child
      link="shoulder_link" />
    <axis
      xyz="1 0 0" />
    <limit
      lower="-0.785"
      upper="0"
      effort="1"
      velocity="1" />
  </joint>
  <link
    name="upperarm_link">
    <inertial>
      <origin
        xyz="-6.4381E-09 1.461E-07 0.012946"
        rpy="0 0 0" />
      <mass
        value="0.00066722" />
      <inertia
        ixx="3.3843E-08"
        ixy="4.6496E-14"
        ixz="-3.0799E-14"
        iyy="3.395E-08"
        iyz="7.5403E-10"
        izz="7.4625E-09" />
    </inertial>
    <visual>
      <origin
        xyz="0 0 0"
        rpy="0 0 0" />
      <geometry>
        <mesh
          filename="package://B_snake_URDF.SLDASM/meshes/upperarm_link.STL" />
      </geometry>
      <material
        name="">
        <color
          rgba="0.79216 0.81961 0.93333 1" />
      </material>
    </visual>
    <collision>
      <origin
        xyz="0 0 0"
        rpy="0 0 0" />
      <geometry>
        <mesh
          filename="package://B_snake_URDF.SLDASM/meshes/upperarm_link.STL" />
      </geometry>
    </collision>
  </link>
  <joint
    name="shoulder_joint_dist"
    type="revolute">
    <origin
      xyz="0 0 0.005"
      rpy="0 0 -3.1416" />
    <parent
      link="shoulder_link" />
    <child
      link="upperarm_link" />
    <axis
      xyz="-1 0 0" />
    <limit
      lower="0"
      upper="0.785"
      effort="1"
      velocity="1" />
  </joint>
  <link
    name="elbow_link">
    <inertial>
      <origin
        xyz="5.7843E-08 -0.00055751 0.0025749"
        rpy="0 0 0" />
      <mass
        value="0.00011415" />
      <inertia
        ixx="7.4251E-10"
        ixy="-5.3952E-14"
        ixz="1.8424E-14"
        iyy="8.8662E-10"
        iyz="-4.9693E-12"
        izz="1.2304E-09" />
    </inertial>
    <visual>
      <origin
        xyz="0 0 0"
        rpy="0 0 0" />
      <geometry>
        <mesh
          filename="package://B_snake_URDF.SLDASM/meshes/elbow_link.STL" />
      </geometry>
      <material
        name="">
        <color
          rgba="0.79216 0.81961 0.93333 1" />
      </material>
    </visual>
    <collision>
      <origin
        xyz="0 0 0"
        rpy="0 0 0" />
      <geometry>
        <mesh
          filename="package://B_snake_URDF.SLDASM/meshes/elbow_link.STL" />
      </geometry>
    </collision>
  </link>
  <joint
    name="elbow_joint_prox"
    type="revolute">
    <origin
      xyz="0 0 0.025"
      rpy="0 0 0" />
    <parent
      link="upperarm_link" />
    <child
      link="elbow_link" />
    <axis
      xyz="1 0 0" />
    <limit
      lower="-0.785"
      upper="0"
      effort="1"
      velocity="1" />
  </joint>
  <link
    name="forearm_link">
    <inertial>
      <origin
        xyz="-1.5817E-08 0.00011358 0.0066338"
        rpy="0 0 0" />
      <mass
        value="0.00027925" />
      <inertia
        ixx="5.1214E-09"
        ixy="-9.0875E-15"
        ixz="-2.1113E-14"
        iyy="5.1602E-09"
        iyz="1.9093E-10"
        izz="3.2376E-09" />
    </inertial>
    <visual>
      <origin
        xyz="0 0 0"
        rpy="0 0 0" />
      <geometry>
        <mesh
          filename="package://B_snake_URDF.SLDASM/meshes/forearm_link.STL" />
      </geometry>
      <material
        name="">
        <color
          rgba="0.79216 0.81961 0.93333 1" />
      </material>
    </visual>
    <collision>
      <origin
        xyz="0 0 0"
        rpy="0 0 0" />
      <geometry>
        <mesh
          filename="package://B_snake_URDF.SLDASM/meshes/forearm_link.STL" />
      </geometry>
    </collision>
  </link>
  <joint
    name="elbow_joint_dist"
    type="revolute">
    <origin
      xyz="0 0 0.005"
      rpy="0 0 3.1416" />
    <parent
      link="elbow_link" />
    <child
      link="forearm_link" />
    <axis
      xyz="-1 0 0" />
    <limit
      lower="0"
      upper="0.785"
      effort="1"
      velocity="1" />
  </joint>
  <link
    name="hand_link">
    <inertial>
      <origin
        xyz="-4.0814E-10 -9.1588E-10 0.011037"
        rpy="0 0 0" />
      <mass
        value="0.00040496" />
      <inertia
        ixx="1.3566E-08"
        ixy="7.1234E-15"
        ixz="-8.9589E-16"
        iyy="1.4395E-08"
        iyz="3.0522E-15"
        izz="3.3828E-09" />
    </inertial>
    <visual>
      <origin
        xyz="0 0 0"
        rpy="0 0 0" />
      <geometry>
        <mesh
          filename="package://B_snake_URDF.SLDASM/meshes/hand_link.STL" />
      </geometry>
      <material
        name="">
        <color
          rgba="0.79216 0.81961 0.93333 1" />
      </material>
    </visual>
    <collision>
      <origin
        xyz="0 0 0"
        rpy="0 0 0" />
      <geometry>
        <mesh
          filename="package://B_snake_URDF.SLDASM/meshes/hand_link.STL" />
      </geometry>
    </collision>
  </link>
  <joint
    name="wrist_joint"
    type="revolute">
    <origin
      xyz="0 0 0.0105"
      rpy="0 0 0" />
    <parent
      link="forearm_link" />
    <child
      link="hand_link" />
    <axis
      xyz="0 0 -1" />
    <limit
      lower="-1.57"
      upper="1.57"
      effort="1"
      velocity="1" />
  </joint>
  <link
    name="gripper_1">
    <inertial>
      <origin
        xyz="-0.00064476 0.0018039 0.0039496"
        rpy="0 0 0" />
      <mass
        value="9.5944E-05" />
      <inertia
        ixx="1.9226E-09"
        ixy="-1.0153E-10"
        ixz="-2.2769E-10"
        iyy="1.7011E-09"
        iyz="-6.335E-10"
        izz="4.994E-10" />
    </inertial>
    <visual>
      <origin
        xyz="0 0 0"
        rpy="0 0 0" />
      <geometry>
        <mesh
          filename="package://B_snake_URDF.SLDASM/meshes/gripper_1.STL" />
      </geometry>
      <material
        name="">
        <color
          rgba="0.79216 0.81961 0.93333 1" />
      </material>
    </visual>
    <collision>
      <origin
        xyz="0 0 0"
        rpy="0 0 0" />
      <geometry>
        <mesh
          filename="package://B_snake_URDF.SLDASM/meshes/gripper_1.STL" />
      </geometry>
    </collision>
  </link>
  <joint
    name="gripper_joint_1"
    type="revolute">
    <origin
      xyz="0 0 0.019"
      rpy="0.3293 0 0" />
    <parent
      link="hand_link" />
    <child
      link="gripper_1" />
    <axis
      xyz="-1 0 0" />
    <limit
      lower="-0.785"
      upper="0"
      effort="1"
      velocity="1" />
  </joint>
  <link
    name="gripper_2">
    <inertial>
      <origin
        xyz="-0.00064476 0.0018039 0.0039496"
        rpy="0 0 0" />
      <mass
        value="9.5944E-05" />
      <inertia
        ixx="1.9226E-09"
        ixy="-1.0153E-10"
        ixz="-2.2769E-10"
        iyy="1.7011E-09"
        iyz="-6.335E-10"
        izz="4.994E-10" />
    </inertial>
    <visual>
      <origin
        xyz="0 0 0"
        rpy="0 0 0" />
      <geometry>
        <mesh
          filename="package://B_snake_URDF.SLDASM/meshes/gripper_2.STL" />
      </geometry>
      <material
        name="">
        <color
          rgba="0.79216 0.81961 0.93333 1" />
      </material>
    </visual>
    <collision>
      <origin
        xyz="0 0 0"
        rpy="0 0 0" />
      <geometry>
        <mesh
          filename="package://B_snake_URDF.SLDASM/meshes/gripper_2.STL" />
      </geometry>
    </collision>
  </link>
  <joint
    name="gripper_2"
    type="revolute">
    <origin
      xyz="0 0 0.019"
      rpy="0.3293 0 3.1416" />
    <parent
      link="hand_link" />
    <child
      link="gripper_2" />
    <axis
      xyz="1 0 0" />
    <limit
      lower="0"
      upper="0.785"
      effort="1"
      velocity="1" />
  </joint>
</robot>